Workbook

Sheet Cover
B15: Prepared By
B16: Analyst | C16: Raman Singh
B17: Company | C17: Reliance Industries Ltd.
B18: Currency | C18: INR (₹)
B19: Report Date | C19: 46247
B21: Valuation Framework
B22: Methodology | C22: Description
B23: Primary Valuation | C23: Sum-of-the-parts (SOTP) Valuation
B24: Secondary Valuation | C24: Discounted Cash Flow (DCF)
B25: Supporting Analysis | C25: Segment-wise DCF Analysis
B26: Market Benchmarking | C26: Relative Valuation (EV/EBITDA, P/E)
B27: Risk Assessment | C27: Sensitivity & Scenario Analysis
B29: Analysis Period
B30: Period | C30: Timeline
B31: Historical Financials | C31: FY2021-22 to FY2025-26
B32: Forecast Period | C32: FY2026-27E to FY2030-31E
B34: Valuation Summary
B35: Valuation Metric | C35: Output Cell
B36: SOTP Intrinsic Target Price | C36: ='13_Executive_Summary'!B7 -> 1397.149
B37: DCF Intrinsic Target Price | C37: ='13_Executive_Summary'!B8 -> 1344.9807
B38: Current NSE Market Price (As of Aug 12, 2026) | C38: ='13_Executive_Summary'!B9 -> 1310
B39: Weighted Target Price (SOTP:0.8, DCF:0.2) | C39: ='13_Executive_Summary'!B10 -> 1386.7154
B40: RECOMMENDATION | C40: =IF((C39/C38-1)>25%,"STRONG BUY", IF((C39/C38-1)>15%,"BUY", IF((C39/C38-1)>0%,"HOLD","SELL"))) -> HOLD

Sheet 01_Overview
B2: MODEL OVERVIEW & KEY ASSUMPTIONS
B4: Valuation Approach | C4: Blended Sum-of-the-Parts (SOTP) & Discounted Cash Flow (DCF)
B6: Forecast Period | C6: FY 2026-27 to FY 2030-31
B7: Terminal Growth Rate | C7: ='07_Forecast_assumptions'!C11/100 -> 0.05
B9: Key Assumptions
B10: Risk Free Rate | C10: 0.0684 | D10: 10 Year GOI Bond Yield
B11: Equity Risk Premium | C11: 0.075 | D11: Market risk premium for India
B12: Tax Rate | C12: 0.2517 | D12: Effective Tax Rate
B13: Terminal Value Methodology | C13: Gordon Growth
B14: Shares Outstanding | C14: 1,353.25 Cr

Sheet 02_Consolidated_Historical_Data
A1: RELIANCE INDUSTRIES LIMITED
A2: PROFIT & LOSS STATEMENT (CONSOLIDATED)
A3: (₹ in Crore)
A5: Consolidated Line Item | B5: FY 2021-22 | C5: FY 2022-23 | D5: FY 2023-24 | E5: FY 2024-25 | F5: FY 2025-26
A6: Revenue (Value of Sales & Services) | B6: 788743 | C6: 974864 | D6: 1000122 | E6: 1071174 | F6: 1175919
A7: Revenue from Operations | B7: 699934 | C7: 877035 | D7: 914472 | E7: 980136 | F7: 1075675
A8: Other Income | B8: 14947 | C8: 11713 | D8: 16057 | E8: 17978 | F8: 19252
A9: Total Income | B9: 732578 | C9: 903045 | D9: 930529 | E9: 998114 | F9: 1104637
A11: Raw Material Cost | B11: 374210 | C11: 491230 | D11: 468905 | E11: 498220 | F11: 542110
A12: Purchase of Stock-in-Trade | B12: 102450 | C12: 142105 | D12: 175600 | E12: 192440 | F12: 212305
A13: Employee Benefit Expense | B13: 18775 | C13: 22234 | D13: 25690 | E13: 28559 | F13: 30318
A14: Other Operating Expenses | B14: 80815 | C14: 67546 | D14: 65987 | E14: 77495 | F14: 82031
A16: EBITDA | B16: 123684 | C16: 153920 | D16: 178290 | E16: 183422 | F16: 207911
A17: Depreciation & Amortisation | B17: 29782 | C17: 40303 | D17: 50832 | E17: 53136 | F17: 57688
A19: Financial Cost | B19: 14584 | C19: 19571 | D19: 23118 | E19: 24269 | F19: 27061
A20: Profit Before Tax (PBT) | B20: 88437 | C20: 105759 | D20: 120784 | E20: 123995 | F20: 142414
... A29: Diluted EPS (₹) | B29: 89.5 | C29: 98 | D29: 102.9 | E29: 51.5 | F29: 59.7
A49: KPIs
A50: Revenue % automotive y-o-y
A51: Revenue % generation y-o-y
A52: Revenue % services y-o-y
A53: GP% automotive
A54: GP% energy generation and automotive
A55: GP% services and other
A56: Overall GP%
A57: EBIT %
A58: Net loss %
A59: ROA
A60: ROE

Sheet 03_Consolidated_Balance_Sheet_
A1: RELIANCE INDUSTRIES LIMITED
A2: BALANCE SHEET (CONSOLIDATED)
A3: (₹ in Crore)
A5: Consolidated Line Item | B5: FY 2021-22 | C5: FY 2022-23 | D5: FY 2023-24 | E5: FY 2024-25 | F5: FY 2025-26 | I5: Consolidated Line Item | J5: FY 2021-22 | K5: FY 2022-23 | L5: FY 2023-24 | M5: FY 2024-25 | N5: FY 2025-26
A6: ASSETS | I6: EQUITIES AND LIABILITIES
A7: NON-CURRENT ASSETS | I7: EQUITY
A8: Property, Plant & Equipment ₹ Crore | B8: 532042 | C8: 570503 | D8: 606084 | E8: 683102 | F8: 751087 | I8: Equity Share Capital ₹ Crore | J8: 6765 | K8: 6766 | L8: 6766 | M8: 13532 | N8: 13532
A9: Capital Work-in-Progress ₹ Crore | B9: 165410 | C9: 117259 | D9: 152382 | E9: 169710 | F9: 192287 | I9: Other Equity ₹ Crore | J9: 638362 | K9: 662114 | L9: 781537 | M9: 829668 | N9: 890498
A10: Spectrum & Related Assets ₹ Crore | B10: 122313 | C10: 197708 | D10: 199454 | E10: 201298 | F10: 196731 | I10: Non-Controlling Interest ₹ Crore | J10: 109110 | K10: 119104 | L10: 132307 | M10: 166426 | N10: 181836
A11: Goodwill & Intangible Assets ₹ Crore | B11: 89421 | C11: 133087 | D11: 160920 | E11: 207641 | F11: 222376 | I11: TOTAL EQUITY ₹ Crore | J11: 754237 | K11: 787984 | L11: 920610 | M11: 1009626 | N11: 1085866
A12: Non-Current Investments ₹ Crore | B12: 110432 | C12: 117087 | D12: 119502 | E12: 123672 | F12: 150901
A13: Loans & Other Financial Assets ₹ Crore | B13: 3926 | C13: 4048 | D13: 3521 | E13: 6830 | F13: 5725 | I13: NON-CURRENT LIABILITIES
A14: Deferred Tax Assets (Net) ₹ Crore | B14: 1215 | C14: 1549 | D14: 938 | E14: 408 | F14: 594 | I14: Long-Term Borrowings ₹ Crore | J14: 180410 | K14: 224195 | L14: 224195 | M14: 236899 | N14: 270751
A15: Other Non-Current Assets ₹ Crore | B15: 35420 | C15: 40894 | D15: 43085 | E15: 58190 | F15: 64190 | I15: Lease Liabilities ₹ Crore | J15: 14205 | K15: 14584 | L15: 16057 | M15: 17142 | N15: 16198
A16: TOTAL NON-CURRENT ASSETS ₹ Crore | B16: 960179 | C16: 1182135 | D16: 1285886 | E16: 1450851 | F16: 1583891 | I16: Deferred Payment Liabilities ₹ Crore | J16: 78590 | K16: 80815 | L16: 91400 | M16: 104410 | N16: 99552
I17: Deferred Tax Liabilities (Net) ₹ Crore | J17: 48200 | K17: 49000 | L17: 50832 | M17: 83453 | N17: 97961
A18: CURRENT ASSETS | I18: Other Non-Current Liabilities ₹ Crore | J18: 28733 | K18: 30403 | L18: 29173 | M18: 44854 | N18: 66558
A19: Inventories ₹ Crore | B19: 107741 | C19: 141114 | D19: 144271 | E19: 146062 | F19: 166941 | I19: TOTAL NON-CURRENT LIABILITIES ₹ Crore | J19: 350138 | K19: 398997 | L19: 421657 | M19: 486758 | N19: 551020
A20: Current Investments ₹ Crore | B20: 141107 | C20: 112390 | D20: 118709 | E20: 118709 | F20: 97431
A21: Trade Receivables ₹ Crore | B21: 18775 | C21: 19811 | D21: 21410 | E21: 42121 | F21: 58491 | I21: CURRENT LIABILITIES
A22: Cash & Cash Equivalents ₹ Crore | B22: 36178 | C22: 6851 | D22: 10211 | E22: 106502 | F22: 145977 | I22: Short-Term Borrowings ₹ Crore | J22: 44213 | K22: 48200 | L22: 103670 | M22: 110631 | N22: 103670
A23: Current Loans & Financial Assets ₹ Crore | B23: 23715 | C23: 22542 | D23: 29560 | E23: 28728 | F23: 62796 | I23: Current Lease Liabilities ₹ Crore | J23: 4114 | K23: 4147 | L23: 4903 | M23: 4903 | N23: 7381
A24: Other Current Assets ₹ Crore | B24: 27249 | C24: 31500 | D24: 36000 | E24: 57148 | F24: 62613 | I24: Trade Payables ₹ Crore | J24: 102450 | K24: 142105 | L24: 132912 | M24: 186789 | N24: 158842
A25: TOTAL CURRENT ASSETS ₹ Crore | B25: 354765 | C25: 334208 | D25: 360161 | E25: 499270 | F25: 594249 | I25: Other Current Financial Liabilities ₹ Crore | J25: 22434 | K25: 27170 | L25: 25690 | M25: 57143 | N25: 64660
I26: Other Current Liabilities ₹ Crore | J26: 32856 | K26: 103670 | L26: 31500 | M26: 90124 | N26: 201503
A27: TOTAL ASSETS ₹ Crore | B27: =SUM(B16+B25) -> 1314944 | C27: =SUM(C16+C25) -> 1516343 | D27: =SUM(D16+D25) -> 1646047 | E27: =SUM(E16+E25) -> 1950121 | F27: =SUM(F16+F25) -> 2178140 | I27: Current Provisions ₹ Crore | J27: 4502 | K27: 4070 | L27: 5105 | M27: 4147 | N27: 5198
I28: TOTAL CURRENT LIABILITIES ₹ Crore | J28: 210569 | K28: 329362 | L28: 303780 | M28: 453737 | N28: 541254
I30: TOTAL LIABILITIES ₹ Crore | J30: 560707 | K30: 728359 | L30: 725437 | M30: 940495 | N30: 1092274
I32: TOTAL EQUITY AND LIABILITIES ₹ Crore | J32: 1314944 | K32: 1516343 | L32: 1646047 | M32: 1950121 | N32: 2178140

Sheet 04_Consolidated_Cash_Flow
A1: RELIANCE INDUSTRIES LIMITED
A2: CASH FLOW (CONSOLIDATED)
A3: (₹ in Crore)
A5: Particular Units | B5: FY 2021-22 | C5: FY 2022-23 | D5: FY 2023-24 | E5: FY 2024-25 | F5: FY 2025-26
A6: Operating Cash Flow (CFO) ₹ Crore (A) | B6: 110654 | C6: 115020 | D6: 158788 | E6: 178703 | F6: 192113
A8: Capital Expenditure (CAPEX) ₹ Crore {PPE + Spectrum + Intangibles} | B8: -109162 | C8: -93001 | D8: -152883 | E8: -139967 | F8: -122916
A9: Other Investing Activities | B9: =B8-B10 -> 941 | C9: =C8-C10 -> -1766 | D9: =D8-D10 -> -38582 | E9: =E8-E10 -> -2432 | F9: =F8-F10 -> -21827
A10: Net Invested Cash Flow - (B) | B10: =-110103 -> -110103 | C10: -91235 | D10: -114301 | E10: -137535 | F10: -101089
A12: Debt Raised / (Repaid) ₹ Crore | B12: 22372 | C12: 16544 | D12: -9880 | E12: -24448 | F12: -44106
A13: Dividends Paid ₹ Crore | B13: -5083 | C13: -6089 | D13: -6766 | E13: -7443 | F13: -7443
A15: Financing Cash Flow (Calculated) ₹ Crore - (C) | B15: =SUM(B12:B13) -> 17289 | C15: =SUM(C12:C13) -> 10455 | D15: =SUM(D12:D13) -> -16646 | E15: =SUM(E12:E13) -> -31891 | F15: =SUM(F12:F13) -> -51549
A17: Net Increase in Cash & Cash Equiv. (A+B+C) | B17: =SUM(B6,B10,B15) -> 17840 | C17: =SUM(C6,C10,C15) -> 34240 | D17: =SUM(D6,D10,D15) -> 27841 | E17: =SUM(E6,E10,E15) -> 9277 | F17: =SUM(F6,F10,F15) -> 39475
A18: (+) Opening Balance of Cash & Cash Equiv. ₹ Crore | B18: 18338 | C18: 34412 | D18: 69384 | E18: 97225 | F18: 106502
A20: (=) Closing Balance of Cash & Cash Equiv. ₹ Crore | B20: =SUM(B17:B18) -> 36178 | C20: =SUM(C17:C18) -> 68652 | D20: =SUM(D17:D18) -> 97225 | E20: =SUM(E17:E18) -> 106502 | F20: =SUM(F17:F18) -> 145977

Sheet 05_Segment_Historical_Raw_Data
A1: RELIANCE INDUSTRIES LIMITED
A2: PROFIT & LOSS STATEMENT (SEGMENT WISE)
A3: (₹ in Crore)
A5: Line Item | B5: FY 2021-22 | C5: FY 2022-23 | D5: FY 2023-24 | E5: FY 2024-25 | F5: FY 2025-26
A6: Oil-to-Chemical (O2C) Segment
A7: Revenue (Value of Sales & Services) | B7: 584298 | C7: 631425 | D7: 564749 | E7: 626921 | F7: 662401
A8: Revenue Growth % | B8: - | C8: =C7/B7-1 -> 0.080655761 | D8: =D7/C7-1 -> -0.10559607 | E8: =E7/D7-1 -> 0.11008784 | F8: =F7/E7-1 -> 0.056594053
A9: EBITDA | B9: 76701 | C9: 62128 | D9: 62389 | E9: 54988 | F9: 60546
A10: EBITDA Margin % | B10: =B9/B7 -> 0.13127034 | C10: =C9/C7 -> 0.098393317 | D10: =D9/D7 -> 0.11047209 | E10: =E9/E7 -> 0.087711211 | F10: =F9/F7 -> 0.091403848
A11: Segment Result (EBIT) - Reported | B11: 63705 | C11: 52620 | D11: 53613 | E11: 47257 | F11: 50758
A12: EBIT Margin % | B12: =B11/B7 -> 0.10902827 | C12: =C11/C7 -> 0.083335313 | D12: =D11/D7 -> 0.094932439 | E12: =E11/E7 -> 0.075379514 | F12: =F11/F7 -> 0.0766273
A13: Capital Expenditure | B13: 20732 | C13: 19511 | D13: 21589 | E13: 26573 | F13: 32365
A14: Depreciation - Reported | B14: 6951 | C14: 7508 | D14: 7297 | E14: 7731 | F14: 9788
A15: Production Meant for Sale MMT | B15: 71.5 | C15: 71.4 | D15: 71.6 | E15: 71.2 | F15: 70.9
A16: Refinery Throughput MMT | B16: 70.3 | C16: 78.2 | D16: 78.2 | E16: 79.4 | F16: 80
A17: Gross Refining Margin (GRM) $/bbl | B17: 9.4 | C17: 10 | D17: 12.8 | E17: 10.7 | F17: 11
A18: Refining Utilisation % | B18: 1.01 | C18: 1.05 | D18: 1.05 | E18: 1.06 | F18: 1.07
A20: Digital Services
A21: Revenue (Value of Sales & Services) | B21: 94547 | C21: 115099 | D21: 132938 | E21: 154119 | F21: 176164
A22: Revenue from Operations | B22: 81634 | C22: 99842 | D22: 113176 | E22: 131336 | F22: 149965
A23: Revenue Growth % | B23: - | C23: =C22/B22-1 -> 0.22304432 | D23: =D22/C22-1 -> 0.13355101 | E23: =E22/D22-1 -> 0.16045805 | F23: =F22/E22-1 -> 0.1418423
A24: EBITDA | B24: 39526 | C24: 49122 | D24: 56675 | E24: 65001 | F24: 76560
A25: EBITDA Margin % | B25: 0.484 | C25: 0.492 | D25: 0.501 | E25: 0.495 | F25: 0.511
A26: Segment EBIT | B26: 25321 | C26: 30172 | D26: 34572 | E26: 40379 | F26: 49311
A27: EBIT Margin % | B27: 0.31 | C27: 0.302 | D27: 0.305 | E27: 0.307 | F27: 0.329
A28: Capital Expenditure | B28: 29100 | C28: 49000 | D28: 44413 | E28: 36000 | F28: 31500
A29: Depreciation - Reported | B29: 14205 | C29: 18950 | D29: 22103 | E29: 24622 | F29: 27249
A30: Subscriber Base (Million) | B30: 410.2 | C30: 439.3 | D30: 481.8 | E30: 488.2 | F30: 524.4
A31: ARPU /month | B31: 167.6 | C31: 178.2 | D31: 181.7 | E31: 206.2 | F31: 214
A32: Data Traffic Bn GB | B32: 91.4 | C32: 113.3 | D32: 148.5 | E32: 184.5 | F32: 241.4
A34: Reliance Retail
A35: Revenue (Value of Sales & Services) | B35: 199704 | C35: 260364 | D35: 306786 | E35: 330943 | F35: 371085
A36: Revenue from Operations | B36: 174980 | C36: 230931 | D36: 273079 | E36: 291043 | F36: 328202
A37: EBITDA | B37: 12381 | C37: 17928 | D37: 23040 | E37: 25094 | F37: 27034
A38: EBITDA Margin % | B38: =B37/B36 -> 0.070756658 | C38: =C37/C36 -> 0.077633579 | D38: =D37/D36 -> 0.084371189 | E38: =E37/E36 -> 0.086220936 | F38: =F37/F36 -> 0.082370004
A39: Segment EBIT | B39: 9512 | C39: 13425 | D39: 17351 | E39: 18349 | F39: 19166
A40: EBIT Margin % | B40: =B39/B36 -> 0.054360498 | C40: =C39/C36 -> 0.058134248 | D40: =D39/D36 -> 0.06353839 | E40: =E39/E36 -> 0.063045667 | F40: =F39/F36 -> 0.058396963
A41: Capital Expenditure | B41: 10500 | C41: 17400 | D41: 26100 | E41: 19500 | F41: 16200
A42: Depreciation - Reported | B42: 2869 | C42: 4503 | D42: 5689 | E42: 6745 | F42: 7868
A43: Registered Customer Base in Mn | B43: 193 | C43: 249 | D43: 304 | E43: 349 | F43: 387
...

Sheet 06_Calculated_Ratios
A1: RELIANCE INDUSTRIES LIMITED
A2: CALCULATED RATIOS (CONSOLIDATED & SEGMENT WISE )
A4: Growth Analysis (₹ Crore) | B4: FY 2021-22 | C4: FY 2022-23 | D4: FY 2023-24 | E4: FY 2024-25 | F4: FY 2025-26
A5: Revenue Growth % | B5: NM | C5: ='02_Consolidated_Historical_Data'!C7/'02_Consolidated_Historical_Data'!B7-1 -> 0.25302529 | D5: ='02_Consolidated_Historical_Data'!D7/'02_Consolidated_Historical_Data'!C7-1 -> 0.042685868 | E5: ='02_Consolidated_Historical_Data'!E7/'02_Consolidated_Historical_Data'!D7-1 -> 0.07180537 | F5: ='02_Consolidated_Historical_Data'!F7/'02_Consolidated_Historical_Data'!E7-1 -> 0.097475248
A6: EBITDA Growth % | B6: NM | C6: ='02_Consolidated_Historical_Data'!C16/'02_Consolidated_Historical_Data'!B16-1 -> 0.24446169 | D6: ='02_Consolidated_Historical_Data'!D16/'02_Consolidated_Historical_Data'!C16-1 -> 0.158329 | E6: ='02_Consolidated_Historical_Data'!E16/'02_Consolidated_Historical_Data'!D16-1 -> 0.028784564 | F6: ='02_Consolidated_Historical_Data'!F16/'02_Consolidated_Historical_Data'!E16-1 -> 0.13351179
A7: PAT Growth % | B7: NM | C7: ='02_Consolidated_Historical_Data'!C26/'02_Consolidated_Historical_Data'!B26-1 -> 0.11310891 | D7: ='02_Consolidated_Historical_Data'!D26/'02_Consolidated_Historical_Data'!C26-1 -> 0.072621148 | E7: ='02_Consolidated_Historical_Data'!E26/'02_Consolidated_Historical_Data'!D26-1 -> 0.02896735 | F7: ='02_Consolidated_Historical_Data'!F26/'02_Consolidated_Historical_Data'!E26-1 -> 0.17765561
A8: EPS Growth % | B8: NM | C8: ='02_Consolidated_Historical_Data'!C28/'02_Consolidated_Historical_Data'!B28-1 -> 0.094972067 | D8: ='02_Consolidated_Historical_Data'!D28/'02_Consolidated_Historical_Data'!C28-1 -> 0.05 | E8: ='02_Consolidated_Historical_Data'!E28/'02_Consolidated_Historical_Data'!D28-1 -> -0.49951409 | F8: ='02_Consolidated_Historical_Data'!F28/'02_Consolidated_Historical_Data'!E28-1 -> 0.1592233
A9: EBIT | B9: ='02_Consolidated_Historical_Data'!B16-'02_Consolidated_Historical_Data'!B17 -> 93902 | C9: ='02_Consolidated_Historical_Data'!C16-'02_Consolidated_Historical_Data'!C17 -> 113617 | D9: ='02_Consolidated_Historical_Data'!D16-'02_Consolidated_Historical_Data'!D17 -> 127458 | E9: ='02_Consolidated_Historical_Data'!E16-'02_Consolidated_Historical_Data'!E17 -> 130286 | F9: ='02_Consolidated_Historical_Data'!F16-'02_Consolidated_Historical_Data'!F17 -> 150223
A11: Profitability Margins | B11: FY 2021-22 | C11: FY 2022-23 | D11: FY 2023-24 | E11: FY 2024-25 | F11: FY 2025-26
A12: EBITDA Margin % | B12: ='02_Consolidated_Historical_Data'!B16/'02_Consolidated_Historical_Data'!B7 -> 0.17670809 | C12: ='02_Consolidated_Historical_Data'!C16/'02_Consolidated_Historical_Data'!C7 -> 0.17550041 | D12: ='02_Consolidated_Historical_Data'!D16/'02_Consolidated_Historical_Data'!D7 -> 0.19496496 | E12: ='02_Consolidated_Historical_Data'!E16/'02_Consolidated_Historical_Data'!E7 -> 0.18713934 | F12: ='02_Consolidated_Historical_Data'!F16/'02_Consolidated_Historical_Data'!F7 -> 0.19328422
A13: PAT Margin % | B13: ='02_Consolidated_Historical_Data'!B26/'02_Consolidated_Historical_Data'!B7 -> 0.094557487 | C13: ='02_Consolidated_Historical_Data'!C26/'02_Consolidated_Historical_Data'!C7 -> 0.083998928 | D13: ='02_Consolidated_Historical_Data'!D26/'02_Consolidated_Historical_Data'!D7 -> 0.086410519 | E13: ='02_Consolidated_Historical_Data'!E26/'02_Consolidated_Historical_Data'!E7 -> 0.082956855 | F13: ='02_Consolidated_Historical_Data'!F26/'02_Consolidated_Historical_Data'!F7 -> 0.089017594
A14: EBIT Margin % | B14: =B9/'02_Consolidated_Historical_Data'!B7 -> 0.13415836 | C14: =C9/'02_Consolidated_Historical_Data'!C7 -> 0.12954671 | D14: =D9/'02_Consolidated_Historical_Data'!D7 -> 0.13937879 | E14: =E9/'02_Consolidated_Historical_Data'!E7 -> 0.13292645 | F14: =F9/'02_Consolidated_Historical_Data'!F7 -> 0.13965464
A16: Return Ratios | B16: FY 2021-22 | C16: FY 2022-23 | D16: FY 2023-24 | E16: FY 2024-25 | F16: FY 2025-26
A17: ROE % | B17: ='02_Consolidated_Historical_Data'!B26/('03_Consolidated_Balance_Sheet_'!J11-'03_Consolidated_Balance_Sheet_'!J10) -> 0.10259065 | C17: ='02_Consolidated_Historical_Data'!C26/('03_Consolidated_Balance_Sheet_'!K11-'03_Consolidated_Balance_Sheet_'!K10) -> 0.11013934 | D17: ='02_Consolidated_Historical_Data'!D26/('03_Consolidated_Balance_Sheet_'!L11-'03_Consolidated_Balance_Sheet_'!L10) -> 0.10024064 | E17: ='02_Consolidated_Historical_Data'!E26/('03_Consolidated_Balance_Sheet_'!M11-'03_Consolidated_Balance_Sheet_'!M10) -> 0.09642908 | F17: ='02_Consolidated_Historical_Data'!F26/('03_Consolidated_Balance_Sheet_'!N11-'03_Consolidated_Balance_Sheet_'!N10) -> 0.10591905
A18: Calculated ROCE % | B18: =B9/('03_Consolidated_Balance_Sheet_'!J11+'03_Consolidated_Balance_Sheet_'!J19) -> 0.085027278 | C18: =C9/('03_Consolidated_Balance_Sheet_'!K11+'03_Consolidated_Balance_Sheet_'!K19) -> 0.095719308 | D18: =D9/('03_Consolidated_Balance_Sheet_'!L11+'03_Consolidated_Balance_Sheet_'!L19) -> 0.094957263 | E18: =E9/('03_Consolidated_Balance_Sheet_'!M11+'03_Consolidated_Balance_Sheet_'!M19) -> 0.087067223 | F18: =F9/('03_Consolidated_Balance_Sheet_'!N11+'03_Consolidated_Balance_Sheet_'!N19) -> 0.091773648
A19: ROA % | B19: ='02_Consolidated_Historical_Data'!B26/'03_Consolidated_Balance_Sheet_'!B27 -> 0.050332181 | C19: ='02_Consolidated_Historical_Data'!C26/'03_Consolidated_Balance_Sheet_'!C27 -> 0.048583995 | D19: ='02_Consolidated_Historical_Data'!D26/'03_Consolidated_Balance_Sheet_'!D27 -> 0.04800592 | E19: ='02_Consolidated_Historical_Data'!E26/'03_Consolidated_Balance_Sheet_'!E27 -> 0.041694336 | F19: ='02_Consolidated_Historical_Data'!F26/'03_Consolidated_Balance_Sheet_'!F27 -> 0.043961362
A21: Leverage Ratios (₹ Crore) | B21: FY 2021-22 | C21: FY 2022-23 | D21: FY 2023-24 | E21: FY 2024-25 | F21: FY 2025-26
A22: Total Debt | B22: ='03_Consolidated_Balance_Sheet_'!J14+'03_Consolidated_Balance_Sheet_'!J22 -> 224623 | C22: ='03_Consolidated_Balance_Sheet_'!K14+'03_Consolidated_Balance_Sheet_'!K22 -> 272395 | D22: ='03_Consolidated_Balance_Sheet_'!L14+'03_Consolidated_Balance_Sheet_'!L22 -> 327865 | E22: ='03_Consolidated_Balance_Sheet_'!M14+'03_Consolidated_Balance_Sheet_'!M22 -> 347530 | F22: ='03_Consolidated_Balance_Sheet_'!N14+'03_Consolidated_Balance_Sheet_'!N22 -> 374421
A23: Cash and Cash Equivalent | B23: ='03_Consolidated_Balance_Sheet_'!B22 -> 36178 | C23: ='03_Consolidated_Balance_Sheet_'!C22 -> 6851 | D23: ='03_Consolidated_Balance_Sheet_'!D22 -> 10211 | E23: ='03_Consolidated_Balance_Sheet_'!E22 -> 106502 | F23: ='03_Consolidated_Balance_Sheet_'!F22 -> 145977
A25: Net Debt | B25: =B22-B23 -> 188445 | C25: =C22-C23 -> 265544 | D25: =D22-D23 -> 317654 | E25: =E22-E23 -> 241028 | F25: =F22-F23 -> 228444
A27: Debt/EBITDA | B27: =B22/'02_Consolidated_Historical_Data'!B16 -> 1.8161039 | C27: =C22/'02_Consolidated_Historical_Data'!C16 -> 1.769718 | D27: =D22/'02_Consolidated_Historical_Data'!D16 -> 1.8389422 | E27: =E22/'02_Consolidated_Historical_Data'!E16 -> 1.8947018 | F27: =F22/'02_Consolidated_Historical_Data'!F16 -> 1.8008715
A28: Net Debt/EBITDA | B28: =B25/'02_Consolidated_Historical_Data'!B16 -> 1.5236005 | C28: =C25/'02_Consolidated_Historical_Data'!C16 -> 1.7252079 | D28: =D25/'02_Consolidated_Historical_Data'!D16 -> 1.7816703 | E28: =E25/'02_Consolidated_Historical_Data'!E16 -> 1.3140627 | F28: =F25/'02_Consolidated_Historical_Data'!F16 -> 1.0987586
A29: Interest Coverage Ratio | B29: =B9/'02_Consolidated_Historical_Data'!B19 -> 6.4386999 | C29: =C9/'02_Consolidated_Historical_Data'!C19 -> 5.8053753 | D29: =D9/'02_Consolidated_Historical_Data'!D19 -> 5.5133662 | E29: =E9/'02_Consolidated_Historical_Data'!E19 -> 5.3684124 | F29: =F9/'02_Consolidated_Historical_Data'!F19 -> 5.551273
A31: Working Capital Analysis (₹ Crore) | B31: FY 2021-22 | C31: FY 2022-23 | D31: FY 2023-24 | E31: FY 2024-25 | F31: FY 2025-26
A32: Inventories Days | B32: ='03_Consolidated_Balance_Sheet_'!B19/'02_Consolidated_Historical_Data'!B7*365 -> 56.184533 | C32: ='03_Consolidated_Balance_Sheet_'!C19/'02_Consolidated_Historical_Data'!C7*365 -> 58.728112 | D32: ='03_Consolidated_Balance_Sheet_'!D19/'02_Consolidated_Historical_Data'!D7*365 -> 57.583956 | E32: ='03_Consolidated_Balance_Sheet_'!E19/'02_Consolidated_Historical_Data'!E7*365 -> 54.393094 | F32: ='03_Consolidated_Balance_Sheet_'!F19/'02_Consolidated_Historical_Data'!F7*365 -> 56.646724
A33: Receivable Days | B33: ='03_Consolidated_Balance_Sheet_'!B21/'02_Consolidated_Historical_Data'!B7*365 -> 9.7907446 | C33: ='03_Consolidated_Balance_Sheet_'!C21/'02_Consolidated_Historical_Data'!C7*365 -> 8.244842 | D33: ='03_Consolidated_Balance_Sheet_'!D21/'02_Consolidated_Historical_Data'!D7*365 -> 8.5455323 | E33: ='03_Consolidated_Balance_Sheet_'!E21/'02_Consolidated_Historical_Data'!E7*365 -> 15.685747 | F33: ='03_Consolidated_Balance_Sheet_'!F21/'02_Consolidated_Historical_Data'!F7*365 -> 19.847273
A34: Payable Days | B34: ='03_Consolidated_Balance_Sheet_'!J24/'02_Consolidated_Historical_Data'!B7*365 -> 53.425394 | C34: ='03_Consolidated_Balance_Sheet_'!K24/'02_Consolidated_Historical_Data'!C7*365 -> 59.140542 | D34: ='03_Consolidated_Balance_Sheet_'!L24/'02_Consolidated_Historical_Data'!D7*365 -> 53.050154 | E34: ='03_Consolidated_Balance_Sheet_'!M24/'02_Consolidated_Historical_Data'!E7*365 -> 69.559719 | F34: ='03_Consolidated_Balance_Sheet_'!N24/'02_Consolidated_Historical_Data'!F7*365 -> 53.898557
A35: Cash Conversion Cycle (CCC) | B35: =B32+B33-B34 -> 12.549883 | C35: =C32+C33-C34 -> 7.8324126 | D35: =D32+D33-D34 -> 13.079334 | E35: =E32+E33-E34 -> 0.51912184 | F35: =F32+F33-F34 -> 22.59544
A36: Net Working Capital (NWC) | B36: ='03_Consolidated_Balance_Sheet_'!B19+'03_Consolidated_Balance_Sheet_'!B21-'03_Consolidated_Balance_Sheet_'!J24 -> 24066 | C36: ='03_Consolidated_Balance_Sheet_'!C19+'03_Consolidated_Balance_Sheet_'!C21-'03_Consolidated_Balance_Sheet_'!K24 -> 18820 | D36: ='03_Consolidated_Balance_Sheet_'!D19+'03_Consolidated_Balance_Sheet_'!D21-'03_Consolidated_Balance_Sheet_'!L24 -> 32769 | E36: =-('03_Consolidated_Balance_Sheet_'!E19+'03_Consolidated_Balance_Sheet_'!E21-'03_Consolidated_Balance_Sheet_'!M24) -> -1394 | F36: ='03_Consolidated_Balance_Sheet_'!F19+'03_Consolidated_Balance_Sheet_'!F21-'03_Consolidated_Balance_Sheet_'!N24 -> 66590
A37: Working Capital/ Revenue % | B37: =B36/'02_Consolidated_Historical_Data'!B7 -> 0.034383242 | C37: =C36/'02_Consolidated_Historical_Data'!C7 -> 0.021458665 | D37: =D36/'02_Consolidated_Historical_Data'!D7 -> 0.035833793 | E37: =E36/'02_Consolidated_Historical_Data'!E7 -> -0.0014222516 | F37: =F36/'02_Consolidated_Historical_Data'!F7 -> 0.061905315
A39: Cash Flow Analysis (₹ Crore) | B39: FY 2021-22 | C39: FY 2022-23 | D39: FY 2023-24 | E39: FY 2024-25 | F39: FY 2025-26
A40: Free Cash Flow (FCF) | B40: ='04_Consolidated_Cash_Flow'!B6+'04_Consolidated_Cash_Flow'!B8 -> 1492 | C40: ='04_Consolidated_Cash_Flow'!C6+'04_Consolidated_Cash_Flow'!C8 -> 22019 | D40: ='04_Consolidated_Cash_Flow'!D6+'04_Consolidated_Cash_Flow'!D8 -> 5905 | E40: ='04_Consolidated_Cash_Flow'!E6+'04_Consolidated_Cash_Flow'!E8 -> 38736 | F40: ='04_Consolidated_Cash_Flow'!F6+'04_Consolidated_Cash_Flow'!F8 -> 69197
A41: FCF Margin % | B41: =B40/'02_Consolidated_Historical_Data'!B7 -> 0.0021316296 | C41: =C40/'02_Consolidated_Historical_Data'!C7 -> 0.025106182 | D41: =D40/'02_Consolidated_Historical_Data'!D7 -> 0.0064572781 | E41: =E40/'02_Consolidated_Historical_Data'!E7 -> 0.039521046 | F41: =F40/'02_Consolidated_Historical_Data'!F7 -> 0.06432891
A42: CFO / EBITDA % | B42: ='04_Consolidated_Cash_Flow'!B6/'02_Consolidated_Historical_Data'!B16 -> 0.89465088 | C42: ='04_Consolidated_Cash_Flow'!C6/'02_Consolidated_Historical_Data'!C16 -> 0.74727131 | D42: ='04_Consolidated_Cash_Flow'!D6/'02_Consolidated_Historical_Data'!D16 -> 0.89061641 | E42: ='04_Consolidated_Cash_Flow'!E6/'02_Consolidated_Historical_Data'!E16 -> 0.97427244 | F42: ='04_Consolidated_Cash_Flow'!F6/'02_Consolidated_Historical_Data'!F16 -> 0.92401556
A43: CAPEX / Revenue % | B43: =-'04_Consolidated_Cash_Flow'!B8/'02_Consolidated_Historical_Data'!B7 -> 0.15596042 | C43: =-'04_Consolidated_Cash_Flow'!C8/'02_Consolidated_Historical_Data'!C7 -> 0.10604024 | D43: =-'04_Consolidated_Cash_Flow'!D8/'02_Consolidated_Historical_Data'!D7 -> 0.16718172 | E43: =-'04_Consolidated_Cash_Flow'!E8/'02_Consolidated_Historical_Data'!E7 -> 0.14280365 | F43: =-'04_Consolidated_Cash_Flow'!F8/'02_Consolidated_Historical_Data'!F7 -> 0.11426871
A44: FCF Conversion % | B44: =B40/'04_Consolidated_Cash_Flow'!B6 -> 0.013483471 | C44: =C40/'04_Consolidated_Cash_Flow'!C6 -> 0.19143627 | D44: =D40/'04_Consolidated_Cash_Flow'!D6 -> 0.037187949 | E44: =E40/'04_Consolidated_Cash_Flow'!E6 -> 0.21676189 | F44: =F40/'04_Consolidated_Cash_Flow'!F6 -> 0.36018906
A46: Segment Mix Analysis | B46: FY 2021-22 | C46: FY 2022-23 | D46: FY 2023-24 | E46: FY 2024-25 | F46: FY 2025-26
A47: Segment Revenue Contribution %
A48: Oil-to-Chemicals (O2C) % | B48: ='05_Segment_Historical_Raw_Data'!B7/('05_Segment_Historical_Raw_Data'!B7+'05_Segment_Historical_Raw_Data'!B21+'05_Segment_Historical_Raw_Data'!B35+'05_Segment_Historical_Raw_Data'!B48) -> 0.65947335 | C48: ='05_Segment_Historical_Raw_Data'!C7/('05_Segment_Historical_Raw_Data'!C7+'05_Segment_Historical_Raw_Data'!C21+'05_Segment_Historical_Raw_Data'!C35+'05_Segment_Historical_Raw_Data'!C48) -> 0.6169899 | D48: ='05_Segment_Historical_Raw_Data'!D7/('05_Segment_Historical_Raw_Data'!D7+'05_Segment_Historical_Raw_Data'!D21+'05_Segment_Historical_Raw_Data'!D35+'05_Segment_Historical_Raw_Data'!D48) -> 0.54896569 | E48: ='05_Segment_Historical_Raw_Data'!E7/('05_Segment_Historical_Raw_Data'!E7+'05_Segment_Historical_Raw_Data'!E21+'05_Segment_Historical_Raw_Data'!E35+'05_Segment_Historical_Raw_Data'!E48) -> 0.55128764 | F48: ='05_Segment_Historical_Raw_Data'!F7/('05_Segment_Historical_Raw_Data'!F7+'05_Segment_Historical_Raw_Data'!F21+'05_Segment_Historical_Raw_Data'!F35+'05_Segment_Historical_Raw_Data'!F48) -> 0.53700453
A49: Digital Services (Jio) % | B49: ='05_Segment_Historical_Raw_Data'!B21/('05_Segment_Historical_Raw_Data'!B7+'05_Segment_Historical_Raw_Data'!B21+'05_Segment_Historical_Raw_Data'!B35+'05_Segment_Historical_Raw_Data'!B48) -> 0.10671135 | C49: ='05_Segment_Historical_Raw_Data'!C21/('05_Segment_Historical_Raw_Data'!C7+'05_Segment_Historical_Raw_Data'!C21+'05_Segment_Historical_Raw_Data'!C35+'05_Segment_Historical_Raw_Data'!C48) -> 0.11246771 | D49: ='05_Segment_Historical_Raw_Data'!D21/('05_Segment_Historical_Raw_Data'!D7+'05_Segment_Historical_Raw_Data'!D21+'05_Segment_Historical_Raw_Data'!D35+'05_Segment_Historical_Raw_Data'!D48) -> 0.12922272 | E49: ='05_Segment_Historical_Raw_Data'!E21/('05_Segment_Historical_Raw_Data'!E7+'05_Segment_Historical_Raw_Data'!E21+'05_Segment_Historical_Raw_Data'!E35+'05_Segment_Historical_Raw_Data'!E48) -> 0.13552569 | F49: ='05_Segment_Historical_Raw_Data'!F21/('05_Segment_Historical_Raw_Data'!F7+'05_Segment_Historical_Raw_Data'!F21+'05_Segment_Historical_Raw_Data'!F35+'05_Segment_Historical_Raw_Data'!F48) -> 0.1428151
...

Sheet 07_Forecast_assumptions
A1: RELIANCE INDUSTRIES LIMITED
A2: FORECAST ASSUMPTIONS & DRIVERS (SCENERIO ENGINE) | C2: Master Scenario Switch ID: | D2: 2 | E2: =CHOOSE(D2, "BULL CASE", "BASE CASE", "BEAR CASE") -> BASE CASE
A4: Segment Metrics & Operational Drivers | B4: Unit(s) | C4: FY 2026-27 | D4: FY 2027-28 | E4: FY 2028-29 | F4: FY 2029-30 | G4: FY 2030-31
A5: Corporate Assumptions | I5: Notes
A6: Tax Rate | B6: % | C6: 25.17 | D6: 25.17 | E6: 25.17 | F6: 25.17 | G6: 25.17 | I6: Normalized effective tax rate based on historical average; maintained constant for forecast period
A7: WACC (Active Dynamic Target) | B7: % | C7: =CHOOSE($D$2,C8,C9,C10) -> 10.5 | D7: =CHOOSE($D$2,D8,D9,D10) -> 10.5 | E7: =CHOOSE($D$2,E8,E9,E10) -> 10.5 | F7: =CHOOSE($D$2,F8,F9,F10) -> 10.5 | G7: =CHOOSE($D$2,G8,G9,G10) -> 10.5 | I7: Long-term weighted average cost of capital assumption reflecting Reliance's diversified business mix and risk profile
A8: ├── Bull Case Scenario | B8: % | C8: =C9-0.75 -> 9.75 | D8: =D9-0.75 -> 9.75 | E8: =E9-0.75 -> 9.75 | F8: =F9-0.75 -> 9.75 | G8: =G9-0.75 -> 9.75
A9: ├── Base Case Scenario | B9: % | C9: 10.5 | D9: 10.5 | E9: 10.5 | F9: 10.5 | G9: 10.5
A10: ├── Bear Case Scenario | B10: % | C10: =C9+0.75 -> 11.25 | D10: =D9+0.75 -> 11.25 | E10: =E9+0.75 -> 11.25 | F10: =F9+0.75 -> 11.25 | G10: =G9+0.75 -> 11.25
A11: Terminal Growth Rate (Active) | B11: % | C11: =CHOOSE($D$2,C12,C13,C14) -> 5 | D11: =CHOOSE($D$2,D12,D13,D14) -> 5 | E11: =CHOOSE($D$2,E12,E13,E14) -> 5 | F11: =CHOOSE($D$2,F12,F13,F14) -> 5 | G11: =CHOOSE($D$2,G12,G13,G14) -> 5 | I11: Long-term nominal growth assumption reflecting mature business growth plus inflation
A12: ├── Bull Case Scenario | B12: % | C12: =C13+0.5 -> 5.5 | D12: =D13+0.5 -> 5.5 | E12: =E13+0.5 -> 5.5 | F12: =F13+0.5 -> 5.5 | G12: =G13+0.5 -> 5.5
A13: ├── Base Case Scenario | B13: % | C13: =C14+0.5 -> 5 | D13: =D14+0.5 -> 5 | E13: =E14+0.5 -> 5 | F13: =F14+0.5 -> 5 | G13: =G14+0.5 -> 5
A14: ├── Bear Case Scenario | B14: % | C14: 4.5 | D14: 4.5 | E14: 4.5 | F14: 4.5 | G14: 4.5
A15: Active Conglomerate Discount | B15: % | C15: =CHOOSE($D$2,C16,C17,C18) -> -5 | D15: =CHOOSE($D$2,D16,D17,D18) -> -5 | E15: =CHOOSE($D$2,E16,E17,E18) -> -5 | F15: =CHOOSE($D$2,F16,F17,F18) -> -5 | G15: =CHOOSE($D$2,G16,G17,G18) -> -5
A16: ├── Bull Case Scenario | B16: % | C16: =C17+5 -> 0 | D16: =D17+5 -> 0 | E16: =E17+5 -> 0 | F16: =F17+5 -> 0 | G16: =G17+5 -> 0
A17: ├── Base Case Scenario | B17: % | C17: -5 | D17: -5 | E17: -5 | F17: -5 | G17: -5
A18: ├── Bear Case Scenario | B18: % | C18: =C17-5 -> -10 | D18: =D17-5 -> -10 | E18: =E17-5 -> -10 | F18: =F17-5 -> -10 | G18: =G17-5 -> -10
A20: Oil-to-Chemicals (O2C)
A21: Revenue Growth (Active) | B21: % | C21: =CHOOSE($D$2,C22,C23,C24) -> 0.035435396 | D21: =CHOOSE($D$2,D22,D23,D24) -> 0.035435396 | E21: =CHOOSE($D$2,E22,E23,E24) -> 0.035435396 | F21: =CHOOSE($D$2,F22,F23,F24) -> 0.035435396 | G21: =CHOOSE($D$2,G22,G23,G24) -> 0.035435396 | I21: Based on historical normalized growth trend; mature refining and petrochemical segment with limited volume expansion
A22: ├── Bull Case Scenario | B22: % | C22: =C23+1% -> 0.045435396 | D22: =D23+1% -> 0.045435396 | E22: =E23+1% -> 0.045435396 | F22: =F23+1% -> 0.045435396 | G22: =G23+1% -> 0.045435396
A23: ├── Base Case Scenario | B23: % | C23: =AVERAGE('05_Segment_Historical_Raw_Data'!$C8:$F8) -> 0.035435396 | D23: =AVERAGE('05_Segment_Historical_Raw_Data'!$C8:$F8) -> 0.035435396 | E23: =AVERAGE('05_Segment_Historical_Raw_Data'!$C8:$F8) -> 0.035435396 | F23: =AVERAGE('05_Segment_Historical_Raw_Data'!$C8:$F8) -> 0.035435396 | G23: =AVERAGE('05_Segment_Historical_Raw_Data'!$C8:$F8) -> 0.035435396
A24: ├── Bear Case Scenario | B24: % | C24: =C23-1% -> 0.025435396 | D24: =D23-1% -> 0.025435396 | E24: =E23-1% -> 0.025435396 | F24: =F23-1% -> 0.025435396 | G24: =G23-1% -> 0.025435396
A25: EBITDA Margin (Active) | B25: % | C25: =CHOOSE($D$2,C26,C27,C28) -> 0.096995115 | D25: =CHOOSE($D$2,D26,D27,D28) -> 0.096995115 | E25: =CHOOSE($D$2,E26,E27,E28) -> 0.096995115 | F25: =CHOOSE($D$2,F26,F27,F28) -> 0.096995115 | G25: =CHOOSE($D$2,G26,G27,G28) -> 0.096995115 | I25: Normalized historical EBITDA margin excluding commodity peak years; assumes mid-cycle profitability
A26: ├── Bull Case Scenario | B26: % | C26: =C27+2% -> 0.11699512 | D26: =D27+2% -> 0.11699512 | E26: =E27+2% -> 0.11699512 | F26: =F27+2% -> 0.11699512 | G26: =G27+2% -> 0.11699512
A27: ├── Base Case Scenario | B27: % | C27: =AVERAGE('05_Segment_Historical_Raw_Data'!$C10:$F10) -> 0.096995115 | D27: =AVERAGE('05_Segment_Historical_Raw_Data'!$C10:$F10) -> 0.096995115 | E27: =AVERAGE('05_Segment_Historical_Raw_Data'!$C10:$F10) -> 0.096995115 | F27: =AVERAGE('05_Segment_Historical_Raw_Data'!$C10:$F10) -> 0.096995115 | G27: =AVERAGE('05_Segment_Historical_Raw_Data'!$C10:$F10) -> 0.096995115
A28: ├── Bear Case Scenario | B28: % | C28: =C27-2% -> 0.076995115 | D28: =D27-2% -> 0.076995115 | E28: =E27-2% -> 0.076995115 | F28: =F27-2% -> 0.076995115 | G28: =G27-2% -> 0.076995115
A29: Active O2C Multiple | B29: x | C29: =CHOOSE($D$2,C30,C31,C32) -> 6.5 | D29: =CHOOSE($D$2,D30,D31,D32) -> 6.5 | E29: =CHOOSE($D$2,E30,E31,E32) -> 6.5 | F29: =CHOOSE($D$2,F30,F31,F32) -> 6.5 | G29: =CHOOSE($D$2,G30,G31,G32) -> 6.5 | I29: Premium to Indian Oil's observed multiple, which is used as a reference rather than a direct like-for-like
A30: ├── Bull Case Scenario | B30: x | C30: =C31+1 -> 7.5 | D30: =D31+1 -> 7.5 | E30: =E31+1 -> 7.5 | F30: =F31+1 -> 7.5 | G30: =G31+1 -> 7.5 | I30: benchmark given differences in ownership scale, integration and business mix. The premium reflects Reliance's
A31: ├── Base Case Scenario | B31: x | C31: 6.5 | D31: 6.5 | E31: 6.5 | F31: 6.5 | G31: 6.5 | I31: integrated refining and petrochemical platform,asset complexity, private-sector capital allocation and broader downstream capabilities.
A32: ├── Bear Case Scenario | B32: x | C32: =C31-1 -> 5.5 | D32: =D31-1 -> 5.5 | E32: =E31-1 -> 5.5 | F32: =F31-1 -> 5.5 | G32: =G31-1 -> 5.5
A33: EBIT Margin | B33: % | C33: =AVERAGE('05_Segment_Historical_Raw_Data'!$C12:$F12) -> 0.082568641 | D33: =AVERAGE('05_Segment_Historical_Raw_Data'!$C12:$F12) -> 0.082568641 | E33: =AVERAGE('05_Segment_Historical_Raw_Data'!$C12:$F12) -> 0.082568641 | F33: =AVERAGE('05_Segment_Historical_Raw_Data'!$C12:$F12) -> 0.082568641 | G33: =AVERAGE('05_Segment_Historical_Raw_Data'!$C12:$F12) -> 0.082568641 | I33: Derived from normalized EBITDA margin after depreciation assumptions
A34: GRM Assumption ($/bbl) (Active) | B34: $/bbl | C34: =CHOOSE($D$2,C35,C36,C37) -> 10.78 | D34: =CHOOSE($D$2,D35,D36,D37) -> 10.78 | E34: =CHOOSE($D$2,E35,E36,E37) -> 10.78 | F34: =CHOOSE($D$2,F35,F36,F37) -> 10.78 | G34: =CHOOSE($D$2,G35,G36,G37) -> 10.78 | I34: Historical average Gross Refining Margin used as normalized mid-cycle assumption
A35: ├── Bull Case Scenario | B35: $/bbl | C35: =C36+2.25 -> 13.03 | D35: =D36+2.25 -> 13.03 | E35: =E36+2.25 -> 13.03 | F35: =F36+2.25 -> 13.03 | G35: =G36+2.25 -> 13.03
A36: ├── Base Case Scenario | B36: $/bbl | C36: =AVERAGE('05_Segment_Historical_Raw_Data'!$B17:$F17) -> 10.78 | D36: =AVERAGE('05_Segment_Historical_Raw_Data'!$B17:$F17) -> 10.78 | E36: =AVERAGE('05_Segment_Historical_Raw_Data'!$B17:$F17) -> 10.78 | F36: =AVERAGE('05_Segment_Historical_Raw_Data'!$B17:$F17) -> 10.78 | G36: =AVERAGE('05_Segment_Historical_Raw_Data'!$B17:$F17) -> 10.78
A37: ├── Bear Case Scenario | B37: $/bbl | C37: =C36-2.25 -> 8.53 | D37: =D36-2.25 -> 8.53 | E37: =E36-2.25 -> 8.53 | F37: =F36-2.25 -> 8.53 | G37: =G36-2.25 -> 8.53
A38: CAPEX / Revenue (Active) | B38: % | C38: =CHOOSE($D$2,C39,C40,C41) -> 0.048860132 | D38: =CHOOSE($D$2,D39,D40,D41) -> 0.048860132 | E38: =CHOOSE($D$2,E39,E40,E41) -> 0.048860132 | F38: =CHOOSE($D$2,F39,F40,F41) -> 0.048860132 | G38: =CHOOSE($D$2,G39,G40,G41) -> 0.048860132 | I38: Maintenance and efficiency improvement CAPEX based on normalized historical CAPEX intensity
A39: ├── Bull Case Scenario | B39: % | C39: =C40+1% -> 0.058860132 | D39: =D40+1% -> 0.058860132 | E39: =E40+1% -> 0.058860132 | F39: =F40+1% -> 0.058860132 | G39: =G40+1% -> 0.058860132
A40: ├── Base Case Scenario | B40: % | C40: ='05_Segment_Historical_Raw_Data'!$F13/'05_Segment_Historical_Raw_Data'!$F7 -> 0.048860132 | D40: ='05_Segment_Historical_Raw_Data'!$F13/'05_Segment_Historical_Raw_Data'!$F7 -> 0.048860132 | E40: ='05_Segment_Historical_Raw_Data'!$F13/'05_Segment_Historical_Raw_Data'!$F7 -> 0.048860132 | F40: ='05_Segment_Historical_Raw_Data'!$F13/'05_Segment_Historical_Raw_Data'!$F7 -> 0.048860132 | G40: ='05_Segment_Historical_Raw_Data'!$F13/'05_Segment_Historical_Raw_Data'!$F7 -> 0.048860132
A41: ├── Bear Case Scenario | B41: % | C41: =C40-1% -> 0.038860132 | D41: =D40-1% -> 0.038860132 | E41: =E40-1% -> 0.038860132 | F41: =F40-1% -> 0.038860132 | G41: =G40-1% -> 0.038860132
A43: Digital Services (Jio)
...

Sheet 08_Three_Statement_Projections
A1: RELIANCE INDUSTRIES LIMITED
A2: THREE STATEMENT PROJECTIONS
A3: (₹ in Crore)
A5: Projected P&L
A6: Projected Line Item | B6: FY 2025-26 (Act) | C6: FY 2026-27 (Proj) | D6: FY 2027-28 (Proj) | E6: FY 2028-29 (Proj) | F6: FY 2029-30 (Proj) | G6: FY 2030-31 (Proj)
A7: SEGMENT REVENUE BUILDUP
A8: Oil-to-Chemicals (O2C) Revenue | B8: ='05_Segment_Historical_Raw_Data'!F7 -> 662401 | C8: =B8*(1+'07_Forecast_assumptions'!C21) -> 685873.44 | D8: =C8*(1+'07_Forecast_assumptions'!D21) -> 710177.64 | E8: =D8*(1+'07_Forecast_assumptions'!E21) -> 735343.07 | F8: =E8*(1+'07_Forecast_assumptions'!F21) -> 761400.24 | G8: =F8*(1+'07_Forecast_assumptions'!G21) -> 788380.76
A9: Digital Services (Jio) Revenue | B9: ='05_Segment_Historical_Raw_Data'!F22 -> 149965 | C9: =B9*(1+'07_Forecast_assumptions'!C57)*(1+'07_Forecast_assumptions'!C61) -> 171220.93 | D9: =C9*(1+'07_Forecast_assumptions'!D57)*(1+'07_Forecast_assumptions'!D61) -> 192758.68 | E9: =D9*(1+'07_Forecast_assumptions'!E57)*(1+'07_Forecast_assumptions'!E61) -> 213950.43 | F9: =E9*(1+'07_Forecast_assumptions'!F57)*(1+'07_Forecast_assumptions'!F61) -> 234102.27 | G9: =F9*(1+'07_Forecast_assumptions'!G57)*(1+'07_Forecast_assumptions'!G61) -> 252488.51
A10: Organised Retail Revenue | B10: ='05_Segment_Historical_Raw_Data'!F36 -> 328202 | C10: =B10*(1+'07_Forecast_assumptions'!C67) -> 372196.07 | D10: =C10*(1+'07_Forecast_assumptions'!D67) -> 418365.4 | E10: =D10*(1+'07_Forecast_assumptions'!E67) -> 466078.18 | F10: =E10*(1+'07_Forecast_assumptions'!F67) -> 514571.62 | G10: =F10*(1+'07_Forecast_assumptions'!G67) -> 562964.88
A11: Oil & Gas (E&P) Revenue | B11: ='05_Segment_Historical_Raw_Data'!F48 -> 23861 | C11: =B11*(1+'07_Forecast_assumptions'!C86) -> 25685.468 | D11: =C11*(1+'07_Forecast_assumptions'!D86) -> 27456.797 | E11: =D11*(1+'07_Forecast_assumptions'!E86) -> 29144.356 | F11: =E11*(1+'07_Forecast_assumptions'!F86) -> 30717.053 | G11: =F11*(1+'07_Forecast_assumptions'!G86) -> 32144.239
A12: Other Operations & Adjustments | B12: ='02_Consolidated_Historical_Data'!F6-SUM('08_Three_Statement_Projections'!B8:B11) -> 11490 | C12: =B12*(1+'06_Calculated_Ratios'!$F$5) -> 12609.991 | D12: =C12*(1+'06_Calculated_Ratios'!$F$5) -> 13839.153 | E12: =D12*(1+'06_Calculated_Ratios'!$F$5) -> 15188.127 | F12: =E12*(1+'06_Calculated_Ratios'!$F$5) -> 16668.594 | G12: =F12*(1+'06_Calculated_Ratios'!$F$5) -> 18293.369
A14: Total Revenue | B14: =+SUM(B8:B12) -> 1175919 | C14: =+SUM(C8:C12) -> 1267585.9 | D14: =+SUM(D8:D12) -> 1362597.7 | E14: =+SUM(E8:E12) -> 1459704.2 | F14: =+SUM(F8:F12) -> 1557459.8 | G14: =+SUM(G8:G12) -> 1654271.7
A16: SEGMENT EBITDA BUILDUP
A17: Oil-to-Chemicals (O2C) EBITDA | B17: ='05_Segment_Historical_Raw_Data'!F9 -> 60546 | C17: ='08_Three_Statement_Projections'!C8*'07_Forecast_assumptions'!C27 -> 66526.374 | D17: ='08_Three_Statement_Projections'!D8*'07_Forecast_assumptions'!D27 -> 68883.762 | E17: ='08_Three_Statement_Projections'!E8*'07_Forecast_assumptions'!E27 -> 71324.685 | F17: ='08_Three_Statement_Projections'!F8*'07_Forecast_assumptions'!F27 -> 73852.104 | G17: ='08_Three_Statement_Projections'!G8*'07_Forecast_assumptions'!G27 -> 76469.082
A18: Digital Services (Jio) EBITDA | B18: ='05_Segment_Historical_Raw_Data'!F24 -> 76560 | C18: =C9*'07_Forecast_assumptions'!C47 -> 85028.312 | D18: =D9*'07_Forecast_assumptions'!D47 -> 96687.755 | E18: =E9*'07_Forecast_assumptions'!E47 -> 108387.29 | F18: =F9*'07_Forecast_assumptions'!F47 -> 119766.72 | G18: =G9*'07_Forecast_assumptions'!G47 -> 130435.56
A19: Organised Retail EBITDA | B19: ='05_Segment_Historical_Raw_Data'!F37 -> 27034 | C19: =C10*'07_Forecast_assumptions'!C71 -> 29876.355 | D19: =D10*'07_Forecast_assumptions'!D71 -> 35674.216 | E19: =E10*'07_Forecast_assumptions'!E71 -> 42073.098 | F19: =F10*'07_Forecast_assumptions'!F71 -> 49023.482 | G19: =G10*'07_Forecast_assumptions'!G71 -> 56448.755
A20: Oil & Gas (E&P) EBITDA | B20: ='05_Segment_Historical_Raw_Data'!F49 -> 19050 | C20: =C11*'07_Forecast_assumptions'!C90 -> 20565.521 | D20: =D11*'07_Forecast_assumptions'!D90 -> 21846.484 | E20: =E11*'07_Forecast_assumptions'!E90 -> 23043.498 | F20: =F11*'07_Forecast_assumptions'!F90 -> 24133.393 | G20: =G11*'07_Forecast_assumptions'!G90 -> 25093.966
A21: Other Operations & Adjustments EBITDA | B21: ='02_Consolidated_Historical_Data'!F16-SUM('08_Three_Statement_Projections'!B17:B20) -> 24721 | C21: =B21*(1+'06_Calculated_Ratios'!$F$6) -> 28021.545 | D21: =C21*(1+'06_Calculated_Ratios'!$F$6) -> 31762.752 | E21: =D21*(1+'06_Calculated_Ratios'!$F$6) -> 36003.454 | F21: =E21*(1+'06_Calculated_Ratios'!$F$6) -> 40810.339 | G21: =F21*(1+'06_Calculated_Ratios'!$F$6) -> 46259.001
A23: Total EBITDA | B23: =+SUM(B16:B21) -> 207911 | C23: =+SUM(C16:C21) -> 230018.11 | D23: =+SUM(D16:D21) -> 254854.97 | E23: =+SUM(E16:E21) -> 280832.02 | F23: =+SUM(F16:F21) -> 307586.04 | G23: =+SUM(G16:G21) -> 334706.37
A25: GROUP P&L ROLLUP
A26: Consolidated Group EBITDA | B26: =B23 -> 207911 | C26: =C23 -> 230018.11 | D26: =D23 -> 254854.97 | E26: =E23 -> 280832.02 | F26: =F23 -> 307586.04 | G26: =G23 -> 334706.37
A27: (-) Depreciation & Amortisation | B27: ='02_Consolidated_Historical_Data'!F17 -> 57688 | C27: =B27*(1+0.075) -> 62014.6 | D27: =C27*(1+0.075) -> 66665.695 | E27: =D27*(1+0.075) -> 71665.622 | F27: =E27*(1+0.075) -> 77040.544 | G27: =F27*(1+0.075) -> 82818.585
A28: Consolidated EBIT | B28: =B26-B27 -> 150223 | C28: =C26-C27 -> 168003.51 | D28: =D26-D27 -> 188189.27 | E28: =E26-E27 -> 209166.4 | F28: =F26-F27 -> 230545.5 | G28: =G26-G27 -> 251887.78
A29: (-) Finance Cost (Interest Expense) | B29: =-'02_Consolidated_Historical_Data'!F19 -> -27061 | C29: =B29*(1+'07_Forecast_assumptions'!C107) -> -29694.259 | D29: =C29*(1+'07_Forecast_assumptions'!D107) -> -32583.755 | E29: =D29*(1+'07_Forecast_assumptions'!E107) -> -35754.423 | F29: =E29*(1+'07_Forecast_assumptions'!F107) -> -39233.624 | G29: =F29*(1+'07_Forecast_assumptions'!G107) -> -43051.379
A30: (+) Other Income | B30: 19252 | C30: =B30*(1+5%) -> 20214.6 | D30: =C30*(1+5%) -> 21225.33 | E30: =D30*(1+5%) -> 22286.597 | F30: =E30*(1+5%) -> 23400.926 | G30: =F30*(1+5%) -> 24570.973
A32: Profit Before Tax (PBT) | B32: =B28+B29+B30 -> 142414 | C32: =C28+C29+C30 -> 158523.85 | D32: =D28+D29+D30 -> 176830.85 | E32: =E28+E29+E30 -> 195698.58 | F32: =F28+F29+F30 -> 214712.8 | G32: =G28+G29+G30 -> 233407.37
A34: (-) Tax Expense | B34: -27552 | C34: =-C32*'07_Forecast_assumptions'!C6/100 -> -39900.453 | D34: =-D32*'07_Forecast_assumptions'!D6/100 -> -44508.324 | E34: =-E32*'07_Forecast_assumptions'!E6/100 -> -49257.331 | F34: =-F32*'07_Forecast_assumptions'!F6/100 -> -54043.212 | G34: =-G32*'07_Forecast_assumptions'!G6/100 -> -58748.636
A36: Profit After Tax (PAT) | B36: =B32+B34 -> 114862 | C36: =C32+C34 -> 118623.4 | D36: =D32+D34 -> 132322.52 | E36: =E32+E34 -> 146441.24 | F36: =F32+F34 -> 160669.59 | G36: =G32+G34 -> 174658.74
A38: (-) Non-Controlling Interest (NCI) | B38: =-'02_Consolidated_Historical_Data'!F25 -> -20108 | C38: =-C36* 18% -> -21352.211 | D38: =-D36* 18% -> -23818.054 | E38: =-E36* 18% -> -26359.424 | F38: =-F36* 18% -> -28920.526 | G38: =-G36* 18% -> -31438.573
A39: ='02_Consolidated_Historical_Data'!A24 -> Share of Profit/(Loss) of JVs & Associates | B39: ='02_Consolidated_Historical_Data'!F24 -> 1000 | C39: =B39*1.1 -> 1100 | D39: =C39*1.1 -> 1210 | E39: =D39*1.1 -> 1331 | F39: =E39*1.1 -> 1464.1 | G39: =F39*1.1 -> 1610.51
A41: PAT Final (Attributable to Owners) | B41: =B36+B38+B39 -> 95754 | C41: =C36+C38+C39 -> 98371.185 | D41: =D36+D38+D39 -> 109714.47 | E41: =E36+E38+E39 -> 121412.82 | F41: =F36+F38+F39 -> 133213.16 | G41: =G36+G38+G39 -> 144830.68
A44: Projected Balance Sheet
A45: Projected Line Item | B45: FY 2025-26 (Act) | C45: FY 2026-27 (Proj) | D45: FY 2027-28 (Proj) | E45: FY 2028-29 (Proj) | F45: FY 2029-30 (Proj) | G45: FY 2030-31 (Proj)
A46: ASSETS NON-CURRENT
A47: Property, Plant and Equipment | B47: ='08A_Balance_Sheet_Support_Sched'!C8 -> 751087 | C47: ='08A_Balance_Sheet_Support_Sched'!D8 -> 820885.52 | D47: ='08A_Balance_Sheet_Support_Sched'!E8 -> 893666.33 | E47: ='08A_Balance_Sheet_Support_Sched'!F8 -> 968825.33 | F47: ='08A_Balance_Sheet_Support_Sched'!G8 -> 1045612.7 | G47: ='08A_Balance_Sheet_Support_Sched'!H8 -> 1070828.6
A48: Capital Work in Progress | B48: ='03_Consolidated_Balance_Sheet_'!F9 -> 192287 | C48: =B48*95% -> 182672.65 | D48: =C48*95% -> 173539.02 | E48: =D48*95% -> 164862.07 | F48: =E48*95% -> 156618.96 | G48: =F48*95% -> 148788.02
A49: Spectrum & Related Assets | B49: ='03_Consolidated_Balance_Sheet_'!F10 -> 196731 | C49: =B49 -> 196731 | D49: =C49 -> 196731 | E49: =D49 -> 196731 | F49: =E49 -> 196731 | G49: =F49 -> 196731
A50: Goodwill & Intangible Assets | B50: ='03_Consolidated_Balance_Sheet_'!F11 -> 222376 | C50: =B50 -> 222376 | D50: =C50 -> 222376 | E50: =D50 -> 222376 | F50: =E50 -> 222376 | G50: =F50 -> 222376
A51: Non-Current Investments | B51: ='03_Consolidated_Balance_Sheet_'!F12 -> 150901 | C51: =B51 -> 150901 | D51: =C51 -> 150901 | E51: =D51 -> 150901 | F51: =E51 -> 150901 | G51: =F51 -> 150901
A52: Loans & Other Financial Assets | B52: ='03_Consolidated_Balance_Sheet_'!F13 -> 5725 | C52: =B52 -> 5725 | D52: =C52 -> 5725 | E52: =D52 -> 5725 | F52: =E52 -> 5725 | G52: =F52 -> 5725
...

Sheet 08A_Balance_Sheet_Support_Sched
B3: Projected Line Item | C3: FY 2025-26 (Act) | D3: FY 2026-27 (Proj) | E3: FY 2027-28 (Proj) | F3: FY 2028-29 (Proj) | G3: FY 2029-30 (Proj) | H3: FY 2030-31 (Proj)
B4: PROPERTY, PLANT & EQUIPMENT SCHEDULE (₹ Crore)
B5: Opening PP&E | C5: - | D5: 751087 | E5: 820886 | F5: 894585 | G5: 971340 | H5: 1050124
B6: (+) Capitalisation from CWIP | C6: =C24 -> 0 | D6: =-'08_Three_Statement_Projections'!C122 -> 131813.12 | E6: =-'08_Three_Statement_Projections'!D122 -> 139446.03 | F6: =-'08_Three_Statement_Projections'!E122 -> 145905.95 | G6: =-'08_Three_Statement_Projections'!F122 -> 151313.29 | H6: =-'08_Three_Statement_Projections'!G122 -> 103523.23
B7: Depreciation | C7: =-'08_Three_Statement_Projections'!B27 -> -57688 | D7: =-'08_Three_Statement_Projections'!C27 -> -62014.6 | E7: =-'08_Three_Statement_Projections'!D27 -> -66665.695 | F7: =-'08_Three_Statement_Projections'!E27 -> -71665.622 | G7: =-'08_Three_Statement_Projections'!F27 -> -77040.544 | H7: =-'08_Three_Statement_Projections'!G27 -> -82818.585
B8: Closing PP&E | C8: =D5 -> 751087 | D8: =D5+D6+D7 -> 820885.52 | E8: =E5+E6+E7 -> 893666.33 | F8: =F5+F6+F7 -> 968825.33 | G8: =G5+G6+G7 -> 1045612.7 | H8: =H5+H6+H7 -> 1070828.6
B10: WORKING CAPITAL SCHEDULE
B11: Inventories | C11: ='03_Consolidated_Balance_Sheet_'!F19 -> 166941 | D11: ='08_Three_Statement_Projections'!C14*14.2% -> 179997.2 | E11: ='08_Three_Statement_Projections'!D14*14.2% -> 193488.87 | F11: ='08_Three_Statement_Projections'!E14*14.2% -> 207277.99 | G11: ='08_Three_Statement_Projections'!F14*14.2% -> 221159.29 | H11: ='08_Three_Statement_Projections'!G14*14.2% -> 234906.59
B12: Trade Receivables | C12: ='03_Consolidated_Balance_Sheet_'!F21 -> 58491 | D12: ='08_Three_Statement_Projections'!C14*5% -> 63379.295 | E12: ='08_Three_Statement_Projections'!D14*5% -> 68129.884 | F12: ='08_Three_Statement_Projections'!E14*5% -> 72985.208 | G12: ='08_Three_Statement_Projections'!F14*5% -> 77872.989 | H12: ='08_Three_Statement_Projections'!G14*5% -> 82713.587
B13: Trade Payable | C13: ='03_Consolidated_Balance_Sheet_'!N24 -> 158842 | D13: ='08_Three_Statement_Projections'!C14*13.5% -> 171124.1 | E13: ='08_Three_Statement_Projections'!D14*13.5% -> 183950.69 | F13: ='08_Three_Statement_Projections'!E14*13.5% -> 197060.06 | G13: ='08_Three_Statement_Projections'!F14*13.5% -> 210257.07 | H13: ='08_Three_Statement_Projections'!G14*13.5% -> 223326.69
B16: NCI SCHEDULE
B17: Opening NCI | C17: ='08_Three_Statement_Projections'!B74 -> 181836 | D17: =C19 -> 181836 | E17: =D19 -> 202088 | F17: =E19 -> 224697 | G17: =F19 -> 249725 | H17: =G19 -> 277182
B18: + Share of PAT to NCI | C18: - | D18: 20252 | E18: 22609 | F18: 25028 | G18: 27457 | H18: 29828
B19: Closing NCI | C19: =SUM(C17:C18) -> 181836 | D19: =SUM(D17:D18) -> 202088 | E19: =SUM(E17:E18) -> 224697 | F19: =SUM(F17:F18) -> 249725 | G19: =SUM(G17:G18) -> 277182 | H19: =SUM(H17:H18) -> 307010

Sheet 09_Free_Cash_Flow_Schedule FCFF
A1: RELIANCE INDUSTRIES LIMITED
A2: FREE CASH FLOW SCHEDULE
A3: (₹ in Crore)
A5: Projected Line Item | B5: FY 2026-27 (Proj) | C5: FY 2027-28 (Proj) | D5: FY 2028-29 (Proj) | E5: FY 2029-30 (Proj) | F5: FY 2030-31 (Proj)
A6: EBIT (Operating Profit) | B6: ='08_Three_Statement_Projections'!C28 -> 168003.51 | C6: ='08_Three_Statement_Projections'!D28 -> 188189.27 | D6: ='08_Three_Statement_Projections'!E28 -> 209166.4 | E6: ='08_Three_Statement_Projections'!F28 -> 230545.5 | F6: ='08_Three_Statement_Projections'!G28 -> 251887.78
A7: Tax Rate % | B7: ='07_Forecast_assumptions'!C6 -> 25.17 | C7: ='07_Forecast_assumptions'!D6 -> 25.17 | D7: ='07_Forecast_assumptions'!E6 -> 25.17 | E7: ='07_Forecast_assumptions'!F6 -> 25.17 | F7: ='07_Forecast_assumptions'!G6 -> 25.17
A8: Tax on EBIT | B8: =B6*B7% -> 42286.483 | C8: =C6*C7% -> 47367.24 | D8: =D6*D7% -> 52647.183 | E8: =E6*E7% -> 58028.302 | F8: =F6*F7% -> 63400.155
A9: NOPAT | B9: =B6-B8 -> 125717.02 | C9: =C6-C8 -> 140822.03 | D9: =D6-D8 -> 156519.22 | E9: =E6-E8 -> 172517.2 | F9: =F6-F8 -> 188487.63
A11: (+) Depreciation & Amortisation | B11: ='08_Three_Statement_Projections'!C27 -> 62014.6 | C11: ='08_Three_Statement_Projections'!D27 -> 66665.695 | D11: ='08_Three_Statement_Projections'!E27 -> 71665.622 | E11: ='08_Three_Statement_Projections'!F27 -> 77040.544 | F11: ='08_Three_Statement_Projections'!G27 -> 82818.585
A12: (-) Capital Expenditure (CAPEX) | B12: ='08_Three_Statement_Projections'!C122 -> -131813.12 | C12: ='08_Three_Statement_Projections'!D122 -> -139446.03 | D12: ='08_Three_Statement_Projections'!E122 -> -145905.95 | E12: ='08_Three_Statement_Projections'!F122 -> -151313.29 | F12: ='08_Three_Statement_Projections'!G122 -> -103523.23
A13: (-) Increase in Net Working Capital | B13: =-'08_Three_Statement_Projections'!C115-'08_Three_Statement_Projections'!C116-'08_Three_Statement_Projections'!C117 -> 5662.3963 | C13: =-'08_Three_Statement_Projections'!D115-'08_Three_Statement_Projections'!D116-'08_Three_Statement_Projections'!D117 -> 5415.671 | D13: =-'08_Three_Statement_Projections'!E115-'08_Three_Statement_Projections'!E116-'08_Three_Statement_Projections'!E117 -> 5535.0701 | E13: =-'08_Three_Statement_Projections'!F115-'08_Three_Statement_Projections'!F116-'08_Three_Statement_Projections'!F117 -> 5572.0701 | F13: =-'08_Three_Statement_Projections'!G115-'08_Three_Statement_Projections'!G116-'08_Three_Statement_Projections'!G117 -> 5518.2822
A15: Free Cash Flow to Firm (FCFF) | B15: =B9+B11+B12-B13 -> 50256.106 | C15: =C9+C11+C12-C13 -> 62626.031 | D15: =D9+D11+D12-D13 -> 76743.823 | E15: =E9+E11+E12-E13 -> 92672.376 | F15: =F9+F11+F12-F13 -> 162264.7

Sheet 10_DCF_Valuation
B1: RELIANCE INDUSTRIES LIMITED
B2: DCF VALUATION
B3: (₹ in Crore)
C5: Terminal Growth Rate | D5: ='07_Forecast_assumptions'!C11 -> 5
C6: WACC % | D6: ='07_Forecast_assumptions'!C7 -> 10.5
B8: Projected Line Item | C8: FY 2026-27 (Proj) | D8: FY 2027-28 (Proj) | E8: FY 2028-29 (Proj) | F8: FY 2029-30 (Proj) | G8: FY 2030-31 (Proj)
B9: Projection Year (t) | C9: 1 | D9: 2 | E9: 3 | F9: 4 | G9: 5
B10: Free Cash Flow (FCFF) | C10: ='09_Free_Cash_Flow_Schedule FCFF'!B15 -> 50256.106 | D10: ='09_Free_Cash_Flow_Schedule FCFF'!C15 -> 62626.031 | E10: ='09_Free_Cash_Flow_Schedule FCFF'!D15 -> 76743.823 | F10: ='09_Free_Cash_Flow_Schedule FCFF'!E15 -> 92672.376 | G10: ='09_Free_Cash_Flow_Schedule FCFF'!F15 -> 162264.7
B11: Discount Factor (@10.50%) | C11: =1/(1+$D$6/100)^C9 -> 0.90497738 | D11: =1/(1+$D$6/100)^D9 -> 0.81898405 | E11: =1/(1+$D$6/100)^E9 -> 0.74116204 | F11: =1/(1+$D$6/100)^F9 -> 0.67073487 | G11: =1/(1+$D$6/100)^G9 -> 0.60699989
B13: Present Value (PV) of FCF | C13: =C10*C11 -> 45480.639 | D13: =D10*D11 -> 51289.72 | E13: =E10*E11 -> 56879.608 | F13: =F10*F11 -> 62158.595 | G13: =G10*G11 -> 98494.654
B16: Particular | C16: Amount
B17: FY2030-31 FCFF | C17: =G10 -> 162264.7
B18: Terminal Growth Rate | C18: =D5/100 -> 0.05
B19: WACC | C19: =D6/100 -> 0.105
B20: Terminal Value | C20: =C17*(1+C18)/(C19 -C18) -> 3097780.6
B21: Discount Factor (FY2030-31) | C21: =G11 -> 0.60699989
B22: Present Value of Terminal Value | C22: =C20*C21 -> 1880352.5
B25: Particular | C25: Amount
B26: PV of Explicit FCFF | C26: =SUM(C13:G13) -> 314303.21
B27: Present Value of Terminal Value | C27: =C22 -> 1880352.5
B28: Enterprise Value | C28: =C27+C26 -> 2194655.7
B31: Particular | C31: Amount
B32: Enterprise Value | C32: =C28 -> 2194655.7
B33: (+) Cash & Cash Equivalents | C33: ='08_Three_Statement_Projections'!C62 -> 155350.17
B34: (-) Total Debt | C34: ='08_Three_Statement_Projections'!C79+'08_Three_Statement_Projections'!C88 -> 348074.69
B35: (-) Non-Controlling Interest (NCI) | C35: =-'15_DCF_Sensitivity_Analysis'!C23 -> -181836
B36: Equity Value | C36: =C32+C33-C34+C35 -> 1820095.2
B37: Shares Outstanding (Crore) | C37: =1353.25 -> 1353.25
B39: Implied Share Price | C39: =C36/C37 -> 1344.9807

Sheet 11_SOTP_valuation
A1: RELIANCE INDUSTRIES LIMITED
A2: SOTP VALUATION
A3: (₹ in Crore)
A5: Segment | B5: FY2026-27 EBITDA (₹ Cr) | C5: EV/EBITDA Multiple | D5: Enterprise Value (₹ Cr)
A6: Oil-to-Chemicals (O2C) | B6: ='08_Three_Statement_Projections'!C17 -> 66526.374 | C6: ='07_Forecast_assumptions'!C29 -> 6.5 | D6: =B6*C6 -> 432421.43
A7: Digital Services (Jio) | B7: ='08_Three_Statement_Projections'!C18 -> 85028.312 | C7: ='07_Forecast_assumptions'!C49 -> 15 | D7: =B7*C7 -> 1275424.7
A8: Reliance Retail | B8: ='08_Three_Statement_Projections'!C19 -> 29876.355 | C8: ='07_Forecast_assumptions'!C75 -> 22 | D8: =B8*C8 -> 657279.81
A9: Oil & Gas (E&P) | B9: ='08_Three_Statement_Projections'!C20 -> 20565.521 | C9: ='07_Forecast_assumptions'!C94 -> 5.5 | D9: =B9*C9 -> 113110.37
A10: Other Businesses & Corporate | B10: ='08_Three_Statement_Projections'!C21 -> 28021.545 | C10: 8 | D10: =B10*C10 -> 224172.36
A12: Total Enterprise Value | D12: =SUM(D6:D10) -> 2702408.6
A15: Particular | B15: Amount
A16: Total Enterprise Value | B16: =D12 -> 2702408.6
A17: (+) Cash & Cash Equivalents | B17: ='08_Three_Statement_Projections'!C62 -> 155350.17
A18: (-) Total Debt | B18: =-('08_Three_Statement_Projections'!C79+'08_Three_Statement_Projections'!C88) -> -348074.69
A19: (-) Non-Controlling Interest | B19: =-(D7*0.33+D8*0.15) -> -519482.12
A20: Equity Value | B20: =B16+B17+B18+B19 -> 1990202
A21: Shares Outstanding (Cr) | B21: 1353.25
A23: Implied Share Price | B23: =B20*(1+'07_Forecast_assumptions'!C15/100)/B21 -> 1397.149
A26: SOTP SENSITIVITY ANALYSIS
A27: Jio EV/EBITDA vs Retail EV/EBITDA
B30: =B23 -> 1397.149 | C30: 18 | D30: 20 | E30: 22 | F30: 24 | G30: 26
B31: 13 | C31: 1245.8528 | D31: 1281.5079 | E31: 1317.163 | F31: 1352.8182 | G31: 1388.4733
B32: 14 | C32: 1285.8457 | D32: 1321.5009 | E32: 1357.156 | F32: 1392.8112 | G32: 1428.4663
B33: 15 | C33: 1325.8387 | D33: 1361.4939 | E33: 1397.149 | F33: 1432.8042 | G33: 1468.4593
B34: 16 | C34: 1365.8317 | D34: 1401.4869 | E34: 1437.142 | F34: 1472.7971 | G34: 1508.4523
B35: 17 | C35: 1405.8247 | D35: 1441.4799 | E35: 1477.135 | F35: 1512.7901 | G35: 1548.4453

Sheet 12_Scenario_Analysis_Dashboard
A1: SCENARIO ANALYSIS DASHBOARD
A5: Scenario-Based Valuation Dashboard | B5: Bull Case (Switch = 1) | C5: Base Case (Switch = 2) | D5: Bear Case (Switch = 3)
A6: Jio Subscriber Growth FY27 | B6: ='07_Forecast_assumptions'!C58 -> 0.094149939 | C6: ='07_Forecast_assumptions'!C59 -> 0.074149939 | D6: ='07_Forecast_assumptions'!C60 -> 0.054149939
A7: Retail EBITDA Margin FY27 | B7: ='07_Forecast_assumptions'!C72 -> 0.095270473 | C7: ='07_Forecast_assumptions'!C73 -> 0.080270473 | D7: ='07_Forecast_assumptions'!C74 -> 0.065270473
A8: O2C GRM Assumption ($/bbl) FY27 | B8: ='07_Forecast_assumptions'!C35 -> 13.03 | C8: ='07_Forecast_assumptions'!C36 -> 10.78 | D8: ='07_Forecast_assumptions'!C37 -> 8.53
A9: Consolidated EBITDA FY27 | B9: 240759 | C9: 230018 | D9: 219544
A10: DCF Target Price | B10: 1934.85 | C10: 1344.98 | D10: 624.36
A11: SOTP Target Price | B11: 1834.64 | C11: 1397.15 | D11: 1034.12
A12: Weighted Target Price (DCF:0.2, SOTP:0.8) | B12: =B10*0.2 +B11*0.8 -> 1854.682 | C12: =C10*0.2 +C11*0.8 -> 1386.716 | D12: =D10*0.2 +D11*0.8 -> 952.168
A13: Current NSE Price (₹) | B13: ='13_Executive_Summary'!B9 -> 1310 | C13: =B13 -> 1310 | D13: =C13 -> 1310
A14: Implied Upside / (Downside) | B14: =B12/B13-1 -> 0.41578779 | C14: =C12/C13-1 -> 0.058561832 | D14: =D12/D13-1 -> -0.2731542
A15: Recommendation | B15: =IF(B14>25%,"STRONG BUY",IF(B14>20%,"BUY",IF(B14>0%,"HOLD","SELL"))) -> STRONG BUY | C15: =IF(C14>25%,"STRONG BUY",IF(C14>20%,"BUY",IF(C14>0%,"HOLD","SELL"))) -> HOLD | D15: =IF(D14>25%,"STRONG BUY",IF(D14>20%,"BUY",IF(D14>0%,"HOLD","SELL"))) -> SELL

Sheet 13_Executive_Summary
A1: RELIANCE INDUSTRIES LIMITED
A2: Valuation Summary & Investment Thesis
A4: MASTER INVESTOR BRIEFCASE
A6: Valuation Metric | B6: Output Cell
A7: SOTP Intrinsic Target Price | B7: ='11_SOTP_valuation'!B23 -> 1397.149
A8: DCF Intrinsic Target Price | B8: ='10_DCF_Valuation'!C39 -> 1344.9807
A9: Current NSE Market Price (As of Aug 12, 2026) | B9: 1310
A10: Weighted Target Price (DCF:0.2, SOTP:0.8) | B10: =B8*0.2 +B7*0.8 -> 1386.7154
A11: Implied SOTP Upside/ (Downside) (%) | B11: =B7/B9-1 -> 0.066525967
A12: Weighted Target Upside/ Downside (%) | B12: =B10/B9-1 -> 0.058561343
A13: RECOMMENDATION | B13: =IF(B12>25%,"STRONG BUY", IF(B12>15%,"BUY", IF(B12>0%,"HOLD","SELL"))) -> HOLD
A16: CONSOLIDATED OPERATION & METRIC FORWARD TRACK
A18: Key Group Health Performance Metric | B18: FY 2025-26 (Act) | C18: FY 2026-27 (Proj) | D18: FY 2027-28 (Proj) | E18: FY 2028-29 (Proj) | F18: FY 2029-30 (Proj) | G18: FY 2030-31 (Proj)
A19: Revenue from Operations (₹ Cr) | B19: ='08_Three_Statement_Projections'!B14 -> 1175919 | C19: ='08_Three_Statement_Projections'!C14 -> 1267585.9 | D19: ='08_Three_Statement_Projections'!D14 -> 1362597.7 | E19: ='08_Three_Statement_Projections'!E14 -> 1459704.2 | F19: ='08_Three_Statement_Projections'!F14 -> 1557459.8 | G19: ='08_Three_Statement_Projections'!G14 -> 1654271.7
A20: EBITDA (₹ Cr) | B20: ='08_Three_Statement_Projections'!B23 -> 207911 | C20: ='08_Three_Statement_Projections'!C23 -> 230018.11 | D20: ='08_Three_Statement_Projections'!D23 -> 254854.97 | E20: ='08_Three_Statement_Projections'!E23 -> 280832.02 | F20: ='08_Three_Statement_Projections'!F23 -> 307586.04 | G20: ='08_Three_Statement_Projections'!G23 -> 334706.37
